Workbook
Name Categoria: 'Strutture ricettive'!$A$2:$A$1048576
Name Città: 'Strutture ricettive'!$E$2:$E$1048576
Name Denominazione: 'Strutture ricettive'!$B$2:$B$1048576
Name Indirizzo: 'Strutture ricettive'!$D$2:$D$1048576
Name Indirizzo_di_posta_elettronica: 'Strutture ricettive'!$I$2:$I$1048576
Name Indirizzo_internet: 'Strutture ricettive'!$G$2:$G$1048576
Name Localita: 'Strutture ricettive'!$F$2:$F$1048576
Name Nome_Struttura: '[1]Strutture ricettive'!$B$2:$B$1048576

Sheet Riepilogo
B2: Città | C2: (Tutto)
B4: Categoria di strutture | C4: N. di strutture
B5: ALBERGHI | C5: 814
B6: ALLOGGIAGRITURISTICI | C6: 830
B7: ALLOGGIINAFFITTO | C7: 541
B8: ALTRIALLOGGIPRIVATI | C8: 721
B9: ALTRIESERCIZIRICETTIVI | C9: 13
B10: AREEDISOSTA(PLEINAIR) | C10: 86
B11: BED&BREAKFAST | C11: 1809
B12: CAMPEGGI | C12: 93
B13: CASEPERFERIE | C13: 82
B14: OSTELLIPERLAGIOVENTU' | C14: 30
B15: RESIDENZETURISTICOALBERGHIERE | C15: 52
B16: RIFUGI | C16: 16
... B20: Totale complessivo | C20: 6258

Sheet Strutture ricettive
A1: Categoria | B1: Denominazione | C1: Indirizzo | D1: Città | E1: Localita | F1: Indirizzointernet | G1: Test | H1: Indirizzodipostaelettronica | I1: IndirizzointernetClean | J1: IndirizzodipostaelettronicaClean
A2: ALLOGGIINAFFITTO | B2: 124AFFITTACAMERE | C2: viaSandroPertini55 | D2: TOLENTINO | E2: Non disponibile | F2: Non disponibile | H2: info@124tolentino.it | I2: =IF(BnB[[#This Row],[Test]]="a",BnB[[#This Row],[Indirizzodipostaelettronica]],IF(BnB[[#This Row],[Test]]="b","Non disponibile",IF(BnB[[#This Row],[Test]]="c",BnB[[#This Row],[Indirizzodipostaelettronica]],IF(BnB[[#This Row],[Test]]="d",BnB[[#This Row],[Indirizzodipostaelettronica]],BnB[[#This Row],[Indirizzointernet]])))) -> Non disponibile | J2: =IF(BnB[[#This Row],[Test]]="a",BnB[[#This Row],[Indirizzointernet]],IF(BnB[[#This Row],[Test]]="b",CONCATENATE(BnB[[#This Row],[Indirizzointernet]],"; ",BnB[[#This Row],[Indirizzodipostaelettronica]]),IF(BnB[[#This Row],[Test]]="c",BnB[[#This Row],[Indirizzointernet]],IF(BnB[[#This Row],[Test]]="d",BnB[[#This Row],[Indirizzointernet]],BnB[[#This Row],[Indirizzodipostaelettronica]])))) -> info@124tolentino.it
A3: ALLOGGIINAFFITTO | B3: 2000diDIAMANTINIASSUNTA | C3: viagiacomopuccini9 | D3: SASSOCORVARO | E3: SASSOCORVARO | F3: Non disponibile | H3: fabbrica-delle-idee@libero.it | I3: =IF(BnB[[#This Row],[Test]]="a",BnB[[#This Row],[Indirizzodipostaelettronica]],IF(BnB[[#This Row],[Test]]="b","Non disponibile",IF(BnB[[#This Row],[Test]]="c",BnB[[#This Row],[Indirizzodipostaelettronica]],IF(BnB[[#This Row],[Test]]="d",BnB[[#This Row],[Indirizzodipostaelettronica]],BnB[[#This Row],[Indirizzointernet]])))) -> Non disponibile | J3: =IF(BnB[[#This Row],[Test]]="a",BnB[[#This Row],[Indirizzointernet]],IF(BnB[[#This Row],[Test]]="b",CONCATENATE(BnB[[#This Row],[Indirizzointernet]],"; ",BnB[[#This Row],[Indirizzodipostaelettronica]]),IF(BnB[[#This Row],[Test]]="c",BnB[[#This Row],[Indirizzointernet]],IF(BnB[[#This Row],[Test]]="d",BnB[[#This Row],[Indirizzointernet]],BnB[[#This Row],[Indirizzodipostaelettronica]])))) -> fabbrica-delle-idee@libero.it
A4: STABILIMENTIBALNEARI | B4: 30NODI | C4: viadelgolfo25 | D4: NUMANA | E4: NUMANA | F4: Non disponibile | H4: alexpanocchi@hotmail.com | I4: =IF(BnB[[#This Row],[Test]]="a",BnB[[#This Row],[Indirizzodipostaelettronica]],IF(BnB[[#This Row],[Test]]="b","Non disponibile",IF(BnB[[#This Row],[Test]]="c",BnB[[#This Row],[Indirizzodipostaelettronica]],IF(BnB[[#This Row],[Test]]="d",BnB[[#This Row],[Indirizzodipostaelettronica]],BnB[[#This Row],[Indirizzointernet]])))) -> Non disponibile | J4: =IF(BnB[[#This Row],[Test]]="a",BnB[[#This Row],[Indirizzointernet]],IF(BnB[[#This Row],[Test]]="b",CONCATENATE(BnB[[#This Row],[Indirizzointernet]],"; ",BnB[[#This Row],[Indirizzodipostaelettronica]]),IF(BnB[[#This Row],[Test]]="c",BnB[[#This Row],[Indirizzointernet]],IF(BnB[[#This Row],[Test]]="d",BnB[[#This Row],[Indirizzointernet]],BnB[[#This Row],[Indirizzodipostaelettronica]])))) -> alexpanocchi@hotmail.com
A5: ALLOGGIINAFFITTO | B5: 3JOLIE | C5: vialeCadutidelLavoro1 | D5: SIROLO | E5: SIROLO | F5: www.cameresirolo.com | H5: info@cameresirolo.com | I5: =IF(BnB[[#This Row],[Test]]="a",BnB[[#This Row],[Indirizzodipostaelettronica]],IF(BnB[[#This Row],[Test]]="b","Non disponibile",IF(BnB[[#This Row],[Test]]="c",BnB[[#This Row],[Indirizzodipostaelettronica]],IF(BnB[[#This Row],[Test]]="d",BnB[[#This Row],[Indirizzodipostaelettronica]],BnB[[#This Row],[Indirizzointernet]])))) -> www.cameresirolo.com | J5: =IF(BnB[[#This Row],[Test]]="a",BnB[[#This Row],[Indirizzointernet]],IF(BnB[[#This Row],[Test]]="b",CONCATENATE(BnB[[#This Row],[Indirizzointernet]],"; ",BnB[[#This Row],[Indirizzodipostaelettronica]]),IF(BnB[[#This Row],[Test]]="c",BnB[[#This Row],[Indirizzointernet]],IF(BnB[[#This Row],[Test]]="d",BnB[[#This Row],[Indirizzointernet]],BnB[[#This Row],[Indirizzodipostaelettronica]])))) -> info@cameresirolo.com
A6: STABILIMENTIBALNEARI | B6: 45.COM | D6: SANBENEDETTODELTRONTO | E6: Non disponibile | F6: Non disponibile | H6: Non disponibile | I6: =IF(BnB[[#This Row],[Test]]="a",BnB[[#This Row],[Indirizzodipostaelettronica]],IF(BnB[[#This Row],[Test]]="b","Non disponibile",IF(BnB[[#This Row],[Test]]="c",BnB[[#This Row],[Indirizzodipostaelettronica]],IF(BnB[[#This Row],[Test]]="d",BnB[[#This Row],[Indirizzodipostaelettronica]],BnB[[#This Row],[Indirizzointernet]])))) -> Non disponibile | J6: =IF(BnB[[#This Row],[Test]]="a",BnB[[#This Row],[Indirizzointernet]],IF(BnB[[#This Row],[Test]]="b",CONCATENATE(BnB[[#This Row],[Indirizzointernet]],"; ",BnB[[#This Row],[Indirizzodipostaelettronica]]),IF(BnB[[#This Row],[Test]]="c",BnB[[#This Row],[Indirizzointernet]],IF(BnB[[#This Row],[Test]]="d",BnB[[#This Row],[Indirizzointernet]],BnB[[#This Row],[Indirizzodipostaelettronica]])))) -> Non disponibile
A7: BED&BREAKFAST | B7: 4PINI | C7: ViadellaMadonnetta10/A | D7: ANCONA | E7: ANCONA | F7: http://www.4pini.it | H7: info@4pini.it | I7: =IF(BnB[[#This Row],[Test]]="a",BnB[[#This Row],[Indirizzodipostaelettronica]],IF(BnB[[#This Row],[Test]]="b","Non disponibile",IF(BnB[[#This Row],[Test]]="c",BnB[[#This Row],[Indirizzodipostaelettronica]],IF(BnB[[#This Row],[Test]]="d",BnB[[#This Row],[Indirizzodipostaelettronica]],BnB[[#This Row],[Indirizzointernet]])))) -> http://www.4pini.it | J7: =IF(BnB[[#This Row],[Test]]="a",BnB[[#This Row],[Indirizzointernet]],IF(BnB[[#This Row],[Test]]="b",CONCATENATE(BnB[[#This Row],[Indirizzointernet]],"; ",BnB[[#This Row],[Indirizzodipostaelettronica]]),IF(BnB[[#This Row],[Test]]="c",BnB[[#This Row],[Indirizzointernet]],IF(BnB[[#This Row],[Test]]="d",BnB[[#This Row],[Indirizzointernet]],BnB[[#This Row],[Indirizzodipostaelettronica]])))) -> info@4pini.it
A8: STABILIMENTIBALNEARI | B8: 4SORELLE | C8: vialealcidedegasperi11 | D8: GROTTAMMARE | E8: Non disponibile | F8: Non disponibile | H8: Non disponibile | I8: =IF(BnB[[#This Row],[Test]]="a",BnB[[#This Row],[Indirizzodipostaelettronica]],IF(BnB[[#This Row],[Test]]="b","Non disponibile",IF(BnB[[#This Row],[Test]]="c",BnB[[#This Row],[Indirizzodipostaelettronica]],IF(BnB[[#This Row],[Test]]="d",BnB[[#This Row],[Indirizzodipostaelettronica]],BnB[[#This Row],[Indirizzointernet]])))) -> Non disponibile | J8: =IF(BnB[[#This Row],[Test]]="a",BnB[[#This Row],[Indirizzointernet]],IF(BnB[[#This Row],[Test]]="b",CONCATENATE(BnB[[#This Row],[Indirizzointernet]],"; ",BnB[[#This Row],[Indirizzodipostaelettronica]]),IF(BnB[[#This Row],[Test]]="c",BnB[[#This Row],[Indirizzointernet]],IF(BnB[[#This Row],[Test]]="d",BnB[[#This Row],[Indirizzointernet]],BnB[[#This Row],[Indirizzodipostaelettronica]])))) -> Non disponibile
A9: CAMPEGGI | B9: 4STAGIONI | C9: contradaBrilli1 | D9: SARNANO | E9: SARNANO | F9: www.camping4stagioni.it | H9: quattrostagioni@camping.it | I9: =IF(BnB[[#This Row],[Test]]="a",BnB[[#This Row],[Indirizzodipostaelettronica]],IF(BnB[[#This Row],[Test]]="b","Non disponibile",IF(BnB[[#This Row],[Test]]="c",BnB[[#This Row],[Indirizzodipostaelettronica]],IF(BnB[[#This Row],[Test]]="d",BnB[[#This Row],[Indirizzodipostaelettronica]],BnB[[#This Row],[Indirizzointernet]])))) -> www.camping4stagioni.it | J9: =IF(BnB[[#This Row],[Test]]="a",BnB[[#This Row],[Indirizzointernet]],IF(BnB[[#This Row],[Test]]="b",CONCATENATE(BnB[[#This Row],[Indirizzointernet]],"; ",BnB[[#This Row],[Indirizzodipostaelettronica]]),IF(BnB[[#This Row],[Test]]="c",BnB[[#This Row],[Indirizzointernet]],IF(BnB[[#This Row],[Test]]="d",BnB[[#This Row],[Indirizzointernet]],BnB[[#This Row],[Indirizzodipostaelettronica]])))) -> quattrostagioni@camping.it
A10: ALTRIALLOGGIPRIVATI | B10: 5ALBERI | C10: viaGualdo7 | D10: BELVEDEREOSTRENSE | E10: Non disponibile | F10: www.5alberi.com | H10: info@5alberi.com | I10: =IF(BnB[[#This Row],[Test]]="a",BnB[[#This Row],[Indirizzodipostaelettronica]],IF(BnB[[#This Row],[Test]]="b","Non disponibile",IF(BnB[[#This Row],[Test]]="c",BnB[[#This Row],[Indirizzodipostaelettronica]],IF(BnB[[#This Row],[Test]]="d",BnB[[#This Row],[Indirizzodipostaelettronica]],BnB[[#This Row],[Indirizzointernet]])))) -> www.5alberi.com | J10: =IF(BnB[[#This Row],[Test]]="a",BnB[[#This Row],[Indirizzointernet]],IF(BnB[[#This Row],[Test]]="b",CONCATENATE(BnB[[#This Row],[Indirizzointernet]],"; ",BnB[[#This Row],[Indirizzodipostaelettronica]]),IF(BnB[[#This Row],[Test]]="c",BnB[[#This Row],[Indirizzointernet]],IF(BnB[[#This Row],[Test]]="d",BnB[[#This Row],[Indirizzointernet]],BnB[[#This Row],[Indirizzodipostaelettronica]])))) -> info@5alberi.com
A11: BED&BREAKFAST | B11: 5COLLI | C11: COLLESANT'ANGELO32A | D11: MONTEPRANDONE | E11: Non disponibile | F11: cinquecolli.bnb@hotmail.com | G11: b | H11: bruni.cinzia@hotmail.it | I11: =IF(BnB[[#This Row],[Test]]="a",BnB[[#This Row],[Indirizzodipostaelettronica]],IF(BnB[[#This Row],[Test]]="b","Non disponibile",IF(BnB[[#This Row],[Test]]="c",BnB[[#This Row],[Indirizzodipostaelettronica]],IF(BnB[[#This Row],[Test]]="d",BnB[[#This Row],[Indirizzodipostaelettronica]],BnB[[#This Row],[Indirizzointernet]])))) -> Non disponibile | J11: =IF(BnB[[#This Row],[Test]]="a",BnB[[#This Row],[Indirizzointernet]],IF(BnB[[#This Row],[Test]]="b",CONCATENATE(BnB[[#This Row],[Indirizzointernet]],"; ",BnB[[#This Row],[Indirizzodipostaelettronica]]),IF(BnB[[#This Row],[Test]]="c",BnB[[#This Row],[Indirizzointernet]],IF(BnB[[#This Row],[Test]]="d",BnB[[#This Row],[Indirizzointernet]],BnB[[#This Row],[Indirizzodipostaelettronica]])))) -> cinquecolli.bnb@hotmail.com; bruni.cinzia@hotmail.it
A12: TURISMORURALE | B12: 9CAMERE | C12: viaCave5 | D12: SIROLO | E12: Non disponibile | F12: www.novecamere.it | H12: info@novecamere.it | I12: =IF(BnB[[#This Row],[Test]]="a",BnB[[#This Row],[Indirizzodipostaelettronica]],IF(BnB[[#This Row],[Test]]="b","Non disponibile",IF(BnB[[#This Row],[Test]]="c",BnB[[#This Row],[Indirizzodipostaelettronica]],IF(BnB[[#This Row],[Test]]="d",BnB[[#This Row],[Indirizzodipostaelettronica]],BnB[[#This Row],[Indirizzointernet]])))) -> www.novecamere.it | J12: =IF(BnB[[#This Row],[Test]]="a",BnB[[#This Row],[Indirizzointernet]],IF(BnB[[#This Row],[Test]]="b",CONCATENATE(BnB[[#This Row],[Indirizzointernet]],"; ",BnB[[#This Row],[Indirizzodipostaelettronica]]),IF(BnB[[#This Row],[Test]]="c",BnB[[#This Row],[Indirizzointernet]],IF(BnB[[#This Row],[Test]]="d",BnB[[#This Row],[Indirizzointernet]],BnB[[#This Row],[Indirizzodipostaelettronica]])))) -> info@novecamere.it
A13: ALLOGGIAGRITURISTICI | B13: A3PASSI | C13: viadelCarmine51 | D13: ANCONA | E13: Non disponibile | F13: www.a3passi.com | H13: a3passi@aziendadelcarmine.it | I13: =IF(BnB[[#This Row],[Test]]="a",BnB[[#This Row],[Indirizzodipostaelettronica]],IF(BnB[[#This Row],[Test]]="b","Non disponibile",IF(BnB[[#This Row],[Test]]="c",BnB[[#This Row],[Indirizzodipostaelettronica]],IF(BnB[[#This Row],[Test]]="d",BnB[[#This Row],[Indirizzodipostaelettronica]],BnB[[#This Row],[Indirizzointernet]])))) -> www.a3passi.com | J13: =IF(BnB[[#This Row],[Test]]="a",BnB[[#This Row],[Indirizzointernet]],IF(BnB[[#This Row],[Test]]="b",CONCATENATE(BnB[[#This Row],[Indirizzointernet]],"; ",BnB[[#This Row],[Indirizzodipostaelettronica]]),IF(BnB[[#This Row],[Test]]="c",BnB[[#This Row],[Indirizzointernet]],IF(BnB[[#This Row],[Test]]="d",BnB[[#This Row],[Indirizzointernet]],BnB[[#This Row],[Indirizzodipostaelettronica]])))) -> a3passi@aziendadelcarmine.it
A14: STABILIMENTIBALNEARI | B14: ABBADETTAMARE | C14: lungomaremarconi55 | D14: SANBENEDETTODELTRONTO | E14: SENIGALLIA | F14: info@lapacehotel.it | G14: c | H14: www.lapacehotel.it | I14: =IF(BnB[[#This Row],[Test]]="a",BnB[[#This Row],[Indirizzodipostaelettronica]],IF(BnB[[#This Row],[Test]]="b","Non disponibile",IF(BnB[[#This Row],[Test]]="c",BnB[[#This Row],[Indirizzodipostaelettronica]],IF(BnB[[#This Row],[Test]]="d",BnB[[#This Row],[Indirizzodipostaelettronica]],BnB[[#This Row],[Indirizzointernet]])))) -> www.lapacehotel.it | J14: =IF(BnB[[#This Row],[Test]]="a",BnB[[#This Row],[Indirizzointernet]],IF(BnB[[#This Row],[Test]]="b",CONCATENATE(BnB[[#This Row],[Indirizzointernet]],"; ",BnB[[#This Row],[Indirizzodipostaelettronica]]),IF(BnB[[#This Row],[Test]]="c",BnB[[#This Row],[Indirizzointernet]],IF(BnB[[#This Row],[Test]]="d",BnB[[#This Row],[Indirizzointernet]],BnB[[#This Row],[Indirizzodipostaelettronica]])))) -> info@lapacehotel.it
A15: ALBERGHI | B15: ABBADETTARESORT | C15: viaAbbadetta36 | D15: ACQUAVIVAPICENA | E15: ACQUAVIVAPICENA | F15: www.abbadetta.it | H15: sabrina-riccioni@hotmail.com | I15: =IF(BnB[[#This Row],[Test]]="a",BnB[[#This Row],[Indirizzodipostaelettronica]],IF(BnB[[#This Row],[Test]]="b","Non disponibile",IF(BnB[[#This Row],[Test]]="c",BnB[[#This Row],[Indirizzodipostaelettronica]],IF(BnB[[#This Row],[Test]]="d",BnB[[#This Row],[Indirizzodipostaelettronica]],BnB[[#This Row],[Indirizzointernet]])))) -> www.abbadetta.it | J15: =IF(BnB[[#This Row],[Test]]="a",BnB[[#This Row],[Indirizzointernet]],IF(BnB[[#This Row],[Test]]="b",CONCATENATE(BnB[[#This Row],[Indirizzointernet]],"; ",BnB[[#This Row],[Indirizzodipostaelettronica]]),IF(BnB[[#This Row],[Test]]="c",BnB[[#This Row],[Indirizzointernet]],IF(BnB[[#This Row],[Test]]="d",BnB[[#This Row],[Indirizzointernet]],BnB[[#This Row],[Indirizzodipostaelettronica]])))) -> sabrina-riccioni@hotmail.com
A16: CASEPERFERIE | B16: ABBADIADIELCITO | C16: localita'Elcito1 | D16: SANSEVERINOMARCHE | E16: SANSEVERINOMARCHE | F16: Non disponibile | H16: edo11@libero.it | I16: =IF(BnB[[#This Row],[Test]]="a",BnB[[#This Row],[Indirizzodipostaelettronica]],IF(BnB[[#This Row],[Test]]="b","Non disponibile",IF(BnB[[#This Row],[Test]]="c",BnB[[#This Row],[Indirizzodipostaelettronica]],IF(BnB[[#This Row],[Test]]="d",BnB[[#This Row],[Indirizzodipostaelettronica]],BnB[[#This Row],[Indirizzointernet]])))) -> Non disponibile | J16: =IF(BnB[[#This Row],[Test]]="a",BnB[[#This Row],[Indirizzointernet]],IF(BnB[[#This Row],[Test]]="b",CONCATENATE(BnB[[#This Row],[Indirizzointernet]],"; ",BnB[[#This Row],[Indirizzodipostaelettronica]]),IF(BnB[[#This Row],[Test]]="c",BnB[[#This Row],[Indirizzointernet]],IF(BnB[[#This Row],[Test]]="d",BnB[[#This Row],[Indirizzointernet]],BnB[[#This Row],[Indirizzodipostaelettronica]])))) -> edo11@libero.it
A17: ALBERGHI | B17: ABBAZIACLUBHOTEL | C17: vialeCristoforoColombo107 | D17: MONDOLFO | E17: MONDOLFO | F17: www.clubhotel-marotta.com | H17: info@clubhotel-marotta.com | I17: =IF(BnB[[#This Row],[Test]]="a",BnB[[#This Row],[Indirizzodipostaelettronica]],IF(BnB[[#This Row],[Test]]="b","Non disponibile",IF(BnB[[#This Row],[Test]]="c",BnB[[#This Row],[Indirizzodipostaelettronica]],IF(BnB[[#This Row],[Test]]="d",BnB[[#This Row],[Indirizzodipostaelettronica]],BnB[[#This Row],[Indirizzointernet]])))) -> www.clubhotel-marotta.com | J17: =IF(BnB[[#This Row],[Test]]="a",BnB[[#This Row],[Indirizzointernet]],IF(BnB[[#This Row],[Test]]="b",CONCATENATE(BnB[[#This Row],[Indirizzointernet]],"; ",BnB[[#This Row],[Indirizzodipostaelettronica]]),IF(BnB[[#This Row],[Test]]="c",BnB[[#This Row],[Indirizzointernet]],IF(BnB[[#This Row],[Test]]="d",BnB[[#This Row],[Indirizzointernet]],BnB[[#This Row],[Indirizzodipostaelettronica]])))) -> info@clubhotel-marotta.com
A18: OSTELLIPERLAGIOVENTU' | B18: ABBAZIADISANBIAGIOILCAPRILE | C18: frazioneCampodonico91/b | D18: FABRIANO | E18: FABRIANO | F18: www.sanbiagioincaprile.it | H18: hostellosanbiagio@libero.it | I18: =IF(BnB[[#This Row],[Test]]="a",BnB[[#This Row],[Indirizzodipostaelettronica]],IF(BnB[[#This Row],[Test]]="b","Non disponibile",IF(BnB[[#This Row],[Test]]="c",BnB[[#This Row],[Indirizzodipostaelettronica]],IF(BnB[[#This Row],[Test]]="d",BnB[[#This Row],[Indirizzodipostaelettronica]],BnB[[#This Row],[Indirizzointernet]])))) -> www.sanbiagioincaprile.it | J18: =IF(BnB[[#This Row],[Test]]="a",BnB[[#This Row],[Indirizzointernet]],IF(BnB[[#This Row],[Test]]="b",CONCATENATE(BnB[[#This Row],[Indirizzointernet]],"; ",BnB[[#This Row],[Indirizzodipostaelettronica]]),IF(BnB[[#This Row],[Test]]="c",BnB[[#This Row],[Indirizzointernet]],IF(BnB[[#This Row],[Test]]="d",BnB[[#This Row],[Indirizzointernet]],BnB[[#This Row],[Indirizzodipostaelettronica]])))) -> hostellosanbiagio@libero.it
A19: STABILIMENTIBALNEARI | B19: ABBRONZATISSIMA | C19: viacristoforocolombo11 | D19: FALCONARAMARITTIMA | E19: FALCONARAMARITTIMA | F19: Non disponibile | H19: Non disponibile | I19: =IF(BnB[[#This Row],[Test]]="a",BnB[[#This Row],[Indirizzodipostaelettronica]],IF(BnB[[#This Row],[Test]]="b","Non disponibile",IF(BnB[[#This Row],[Test]]="c",BnB[[#This Row],[Indirizzodipostaelettronica]],IF(BnB[[#This Row],[Test]]="d",BnB[[#This Row],[Indirizzodipostaelettronica]],BnB[[#This Row],[Indirizzointernet]])))) -> Non disponibile | J19: =IF(BnB[[#This Row],[Test]]="a",BnB[[#This Row],[Indirizzointernet]],IF(BnB[[#This Row],[Test]]="b",CONCATENATE(BnB[[#This Row],[Indirizzointernet]],"; ",BnB[[#This Row],[Indirizzodipostaelettronica]]),IF(BnB[[#This Row],[Test]]="c",BnB[[#This Row],[Indirizzointernet]],IF(BnB[[#This Row],[Test]]="d",BnB[[#This Row],[Indirizzointernet]],BnB[[#This Row],[Indirizzodipostaelettronica]])))) -> Non disponibile
A20: ALLOGGIINAFFITTO | B20: ABRAMO | C20: viaannibalcaro80 | D20: PORTORECANATI | E20: PORTORECANATI | F20: www.abramocamere.it | H20: info@abramocamere.it | I20: =IF(BnB[[#This Row],[Test]]="a",BnB[[#This Row],[Indirizzodipostaelettronica]],IF(BnB[[#This Row],[Test]]="b","Non disponibile",IF(BnB[[#This Row],[Test]]="c",BnB[[#This Row],[Indirizzodipostaelettronica]],IF(BnB[[#This Row],[Test]]="d",BnB[[#This Row],[Indirizzodipostaelettronica]],BnB[[#This Row],[Indirizzointernet]])))) -> www.abramocamere.it | J20: =IF(BnB[[#This Row],[Test]]="a",BnB[[#This Row],[Indirizzointernet]],IF(BnB[[#This Row],[Test]]="b",CONCATENATE(BnB[[#This Row],[Indirizzointernet]],"; ",BnB[[#This Row],[Indirizzodipostaelettronica]]),IF(BnB[[#This Row],[Test]]="c",BnB[[#This Row],[Indirizzointernet]],IF(BnB[[#This Row],[Test]]="d",BnB[[#This Row],[Indirizzointernet]],BnB[[#This Row],[Indirizzodipostaelettronica]])))) -> info@abramocamere.it
A21: TURISMORURALE | B21: ACANTOCOUNTRYHOUSE | C21: viaAncarano18 | D21: SIROLO | E21: SIROLO | F21: www.acantocountryhouse.com | H21: info@acantocountryhouse.com | I21: =IF(BnB[[#This Row],[Test]]="a",BnB[[#This Row],[Indirizzodipostaelettronica]],IF(BnB[[#This Row],[Test]]="b","Non disponibile",IF(BnB[[#This Row],[Test]]="c",BnB[[#This Row],[Indirizzodipostaelettronica]],IF(BnB[[#This Row],[Test]]="d",BnB[[#This Row],[Indirizzodipostaelettronica]],BnB[[#This Row],[Indirizzointernet]])))) -> www.acantocountryhouse.com | J21: =IF(BnB[[#This Row],[Test]]="a",BnB[[#This Row],[Indirizzointernet]],IF(BnB[[#This Row],[Test]]="b",CONCATENATE(BnB[[#This Row],[Indirizzointernet]],"; ",BnB[[#This Row],[Indirizzodipostaelettronica]]),IF(BnB[[#This Row],[Test]]="c",BnB[[#This Row],[Indirizzointernet]],IF(BnB[[#This Row],[Test]]="d",BnB[[#This Row],[Indirizzointernet]],BnB[[#This Row],[Indirizzodipostaelettronica]])))) -> info@acantocountryhouse.com
A22: STABILIMENTIBALNEARI | B22: ACAPULCO | D22: PORTORECANATI | E22: PORTORECANATI | F22: Non disponibile | H22: Non disponibile | I22: =IF(BnB[[#This Row],[Test]]="a",BnB[[#This Row],[Indirizzodipostaelettronica]],IF(BnB[[#This Row],[Test]]="b","Non disponibile",IF(BnB[[#This Row],[Test]]="c",BnB[[#This Row],[Indirizzodipostaelettronica]],IF(BnB[[#This Row],[Test]]="d",BnB[[#This Row],[Indirizzodipostaelettronica]],BnB[[#This Row],[Indirizzointernet]])))) -> Non disponibile | J22: =IF(BnB[[#This Row],[Test]]="a",BnB[[#This Row],[Indirizzointernet]],IF(BnB[[#This Row],[Test]]="b",CONCATENATE(BnB[[#This Row],[Indirizzointernet]],"; ",BnB[[#This Row],[Indirizzodipostaelettronica]]),IF(BnB[[#This Row],[Test]]="c",BnB[[#This Row],[Indirizzointernet]],IF(BnB[[#This Row],[Test]]="d",BnB[[#This Row],[Indirizzointernet]],BnB[[#This Row],[Indirizzodipostaelettronica]])))) -> Non disponibile
A23: ALLOGGIAGRITURISTICI | B23: ACASADAANGELO | C23: contradaSanGiacomo26 | D23: GROTTAMMARE | E23: GROTTAMMARE | F23: Non disponibile | H23: agriturismoacasadaangelo@alice.it | I23: =IF(BnB[[#This Row],[Test]]="a",BnB[[#This Row],[Indirizzodipostaelettronica]],IF(BnB[[#This Row],[Test]]="b","Non disponibile",IF(BnB[[#This Row],[Test]]="c",BnB[[#This Row],[Indirizzodipostaelettronica]],IF(BnB[[#This Row],[Test]]="d",BnB[[#This Row],[Indirizzodipostaelettronica]],BnB[[#This Row],[Indirizzointernet]])))) -> Non disponibile | J23: =IF(BnB[[#This Row],[Test]]="a",BnB[[#This Row],[Indirizzointernet]],IF(BnB[[#This Row],[Test]]="b",CONCATENATE(BnB[[#This Row],[Indirizzointernet]],"; ",BnB[[#This Row],[Indirizzodipostaelettronica]]),IF(BnB[[#This Row],[Test]]="c",BnB[[#This Row],[Indirizzointernet]],IF(BnB[[#This Row],[Test]]="d",BnB[[#This Row],[Indirizzointernet]],BnB[[#This Row],[Indirizzodipostaelettronica]])))) -> agriturismoacasadaangelo@alice.it
A24: BED&BREAKFAST | B24: ACASADINONNADICROIAMAURO | C24: VIAABRUZZO7 | D24: LORETO | E24: LORETO | F24: Non disponibile | H24: maurocroia@alice.it | I24: =IF(BnB[[#This Row],[Test]]="a",BnB[[#This Row],[Indirizzodipostaelettronica]],IF(BnB[[#This Row],[Test]]="b","Non disponibile",IF(BnB[[#This Row],[Test]]="c",BnB[[#This Row],[Indirizzodipostaelettronica]],IF(BnB[[#This Row],[Test]]="d",BnB[[#This Row],[Indirizzodipostaelettronica]],BnB[[#This Row],[Indirizzointernet]])))) -> Non disponibile | J24: =IF(BnB[[#This Row],[Test]]="a",BnB[[#This Row],[Indirizzointernet]],IF(BnB[[#This Row],[Test]]="b",CONCATENATE(BnB[[#This Row],[Indirizzointernet]],"; ",BnB[[#This Row],[Indirizzodipostaelettronica]]),IF(BnB[[#This Row],[Test]]="c",BnB[[#This Row],[Indirizzointernet]],IF(BnB[[#This Row],[Test]]="d",BnB[[#This Row],[Indirizzointernet]],BnB[[#This Row],[Indirizzodipostaelettronica]])))) -> maurocroia@alice.it
A25: BED&BREAKFAST | B25: ACASADINONNALINDA | C25: ViaGherardi54 | D25: SENIGALLIA | E25: SENIGALLIA | F25: Non disponibile | H25: info@acasadinonnalinda.it | I25: =IF(BnB[[#This Row],[Test]]="a",BnB[[#This Row],[Indirizzodipostaelettronica]],IF(BnB[[#This Row],[Test]]="b","Non disponibile",IF(BnB[[#This Row],[Test]]="c",BnB[[#This Row],[Indirizzodipostaelettronica]],IF(BnB[[#This Row],[Test]]="d",BnB[[#This Row],[Indirizzodipostaelettronica]],BnB[[#This Row],[Indirizzointernet]])))) -> Non disponibile | J25: =IF(BnB[[#This Row],[Test]]="a",BnB[[#This Row],[Indirizzointernet]],IF(BnB[[#This Row],[Test]]="b",CONCATENATE(BnB[[#This Row],[Indirizzointernet]],"; ",BnB[[#This Row],[Indirizzodipostaelettronica]]),IF(BnB[[#This Row],[Test]]="c",BnB[[#This Row],[Indirizzointernet]],IF(BnB[[#This Row],[Test]]="d",BnB[[#This Row],[Indirizzointernet]],BnB[[#This Row],[Indirizzodipostaelettronica]])))) -> info@acasadinonnalinda.it
A26: BED&BREAKFAST | B26: ACASADIPAOLA | C26: vialeGiovanniXXIII6 | D26: JESI | E26: Non disponibile | F26: www.casapaola.it | H26: info@casapaola.it | I26: =IF(BnB[[#This Row],[Test]]="a",BnB[[#This Row],[Indirizzodipostaelettronica]],IF(BnB[[#This Row],[Test]]="b","Non disponibile",IF(BnB[[#This Row],[Test]]="c",BnB[[#This Row],[Indirizzodipostaelettronica]],IF(BnB[[#This Row],[Test]]="d",BnB[[#This Row],[Indirizzodipostaelettronica]],BnB[[#This Row],[Indirizzointernet]])))) -> www.casapaola.it | J26: =IF(BnB[[#This Row],[Test]]="a",BnB[[#This Row],[Indirizzointernet]],IF(BnB[[#This Row],[Test]]="b",CONCATENATE(BnB[[#This Row],[Indirizzointernet]],"; ",BnB[[#This Row],[Indirizzodipostaelettronica]]),IF(BnB[[#This Row],[Test]]="c",BnB[[#This Row],[Indirizzointernet]],IF(BnB[[#This Row],[Test]]="d",BnB[[#This Row],[Indirizzointernet]],BnB[[#This Row],[Indirizzodipostaelettronica]])))) -> info@casapaola.it
A27: BED&BREAKFAST | B27: ACASADIPETER | C27: VIAO.MARCHETTI24 | D27: CIVITANOVAMARCHE | E27: CIVITANOVAMARCHE | F27: Non disponibile | H27: pietro.forani@virgilio.it | I27: =IF(BnB[[#This Row],[Test]]="a",BnB[[#This Row],[Indirizzodipostaelettronica]],IF(BnB[[#This Row],[Test]]="b","Non disponibile",IF(BnB[[#This Row],[Test]]="c",BnB[[#This Row],[Indirizzodipostaelettronica]],IF(BnB[[#This Row],[Test]]="d",BnB[[#This Row],[Indirizzodipostaelettronica]],BnB[[#This Row],[Indirizzointernet]])))) -> Non disponibile | J27: =IF(BnB[[#This Row],[Test]]="a",BnB[[#This Row],[Indirizzointernet]],IF(BnB[[#This Row],[Test]]="b",CONCATENATE(BnB[[#This Row],[Indirizzointernet]],"; ",BnB[[#This Row],[Indirizzodipostaelettronica]]),IF(BnB[[#This Row],[Test]]="c",BnB[[#This Row],[Indirizzointernet]],IF(BnB[[#This Row],[Test]]="d",BnB[[#This Row],[Indirizzointernet]],BnB[[#This Row],[Indirizzodipostaelettronica]])))) -> pietro.forani@virgilio.it
A28: BED&BREAKFAST | B28: ACASADIROMOLO | C28: viaRamazzani144 | D28: ARCEVIA | E28: ARCEVIA | F28: Non disponibile | H28: acasadiromolo@gmail.com | I28: =IF(BnB[[#This Row],[Test]]="a",BnB[[#This Row],[Indirizzodipostaelettronica]],IF(BnB[[#This Row],[Test]]="b","Non disponibile",IF(BnB[[#This Row],[Test]]="c",BnB[[#This Row],[Indirizzodipostaelettronica]],IF(BnB[[#This Row],[Test]]="d",BnB[[#This Row],[Indirizzodipostaelettronica]],BnB[[#This Row],[Indirizzointernet]])))) -> Non disponibile | J28: =IF(BnB[[#This Row],[Test]]="a",BnB[[#This Row],[Indirizzointernet]],IF(BnB[[#This Row],[Test]]="b",CONCATENATE(BnB[[#This Row],[Indirizzointernet]],"; ",BnB[[#This Row],[Indirizzodipostaelettronica]]),IF(BnB[[#This Row],[Test]]="c",BnB[[#This Row],[Indirizzointernet]],IF(BnB[[#This Row],[Test]]="d",BnB[[#This Row],[Indirizzointernet]],BnB[[#This Row],[Indirizzodipostaelettronica]])))) -> acasadiromolo@gmail.com
A29: ALLOGGIAGRITURISTICI | B29: ACCIPICCHIA | C29: contradacampana146 | D29: ANCONA | E29: collinadiPORTONOVO | F29: www.cantinapolenta.it | H29: info@cantinapolenta.it | I29: =IF(BnB[[#This Row],[Test]]="a",BnB[[#This Row],[Indirizzodipostaelettronica]],IF(BnB[[#This Row],[Test]]="b","Non disponibile",IF(BnB[[#This Row],[Test]]="c",BnB[[#This Row],[Indirizzodipostaelettronica]],IF(BnB[[#This Row],[Test]]="d",BnB[[#This Row],[Indirizzodipostaelettronica]],BnB[[#This Row],[Indirizzointernet]])))) -> www.cantinapolenta.it | J29: =IF(BnB[[#This Row],[Test]]="a",BnB[[#This Row],[Indirizzointernet]],IF(BnB[[#This Row],[Test]]="b",CONCATENATE(BnB[[#This Row],[Indirizzointernet]],"; ",BnB[[#This Row],[Indirizzodipostaelettronica]]),IF(BnB[[#This Row],[Test]]="c",BnB[[#This Row],[Indirizzointernet]],IF(BnB[[#This Row],[Test]]="d",BnB[[#This Row],[Indirizzointernet]],BnB[[#This Row],[Indirizzodipostaelettronica]])))) -> info@cantinapolenta.it
A30: ALLOGGIINAFFITTO | B30: ACCOMODATIONCASACAVOUR | C30: G.MORETTI1 | D30: SANBENEDETTODELTRONTO | E30: Non disponibile | F30: www.casacavoursanbenedetto.it | H30: info@casacavoursanbenedetto.it | I30: =IF(BnB[[#This Row],[Test]]="a",BnB[[#This Row],[Indirizzodipostaelettronica]],IF(BnB[[#This Row],[Test]]="b","Non disponibile",IF(BnB[[#This Row],[Test]]="c",BnB[[#This Row],[Indirizzodipostaelettronica]],IF(BnB[[#This Row],[Test]]="d",BnB[[#This Row],[Indirizzodipostaelettronica]],BnB[[#This Row],[Indirizzointernet]])))) -> www.casacavoursanbenedetto.it | J30: =IF(BnB[[#This Row],[Test]]="a",BnB[[#This Row],[Indirizzointernet]],IF(BnB[[#This Row],[Test]]="b",CONCATENATE(BnB[[#This Row],[Indirizzointernet]],"; ",BnB[[#This Row],[Indirizzodipostaelettronica]]),IF(BnB[[#This Row],[Test]]="c",BnB[[#This Row],[Indirizzointernet]],IF(BnB[[#This Row],[Test]]="d",BnB[[#This Row],[Indirizzointernet]],BnB[[#This Row],[Indirizzodipostaelettronica]])))) -> info@casacavoursanbenedetto.it
A31: ALTRIALLOGGIPRIVATI | B31: ACEROFRANCESCOEFILIPPO | C31: viaMontePolo10 | D31: URBINO | E31: Non disponibile | F31: Non disponibile | H31: m.g.acero@alice.it | I31: =IF(BnB[[#This Row],[Test]]="a",BnB[[#This Row],[Indirizzodipostaelettronica]],IF(BnB[[#This Row],[Test]]="b","Non disponibile",IF(BnB[[#This Row],[Test]]="c",BnB[[#This Row],[Indirizzodipostaelettronica]],IF(BnB[[#This Row],[Test]]="d",BnB[[#This Row],[Indirizzodipostaelettronica]],BnB[[#This Row],[Indirizzointernet]])))) -> Non disponibile | J31: =IF(BnB[[#This Row],[Test]]="a",BnB[[#This Row],[Indirizzointernet]],IF(BnB[[#This Row],[Test]]="b",CONCATENATE(BnB[[#This Row],[Indirizzointernet]],"; ",BnB[[#This Row],[Indirizzodipostaelettronica]]),IF(BnB[[#This Row],[Test]]="c",BnB[[#This Row],[Indirizzointernet]],IF(BnB[[#This Row],[Test]]="d",BnB[[#This Row],[Indirizzointernet]],BnB[[#This Row],[Indirizzodipostaelettronica]])))) -> m.g.acero@alice.it
A32: ALTRIALLOGGIPRIVATI | B32: ACEROMARIAGRAZIA | C32: viaMontePolo8 | D32: URBINO | E32: Non disponibile | F32: Non disponibile | H32: m.g.acero@alice.it | I32: =IF(BnB[[#This Row],[Test]]="a",BnB[[#This Row],[Indirizzodipostaelettronica]],IF(BnB[[#This Row],[Test]]="b","Non disponibile",IF(BnB[[#This Row],[Test]]="c",BnB[[#This Row],[Indirizzodipostaelettronica]],IF(BnB[[#This Row],[Test]]="d",BnB[[#This Row],[Indirizzodipostaelettronica]],BnB[[#This Row],[Indirizzointernet]])))) -> Non disponibile | J32: =IF(BnB[[#This Row],[Test]]="a",BnB[[#This Row],[Indirizzointernet]],IF(BnB[[#This Row],[Test]]="b",CONCATENATE(BnB[[#This Row],[Indirizzointernet]],"; ",BnB[[#This Row],[Indirizzodipostaelettronica]]),IF(BnB[[#This Row],[Test]]="c",BnB[[#This Row],[Indirizzointernet]],IF(BnB[[#This Row],[Test]]="d",BnB[[#This Row],[Indirizzointernet]],BnB[[#This Row],[Indirizzodipostaelettronica]])))) -> m.g.acero@alice.it
A33: ALLOGGIAGRITURISTICI | B33: ACQUABATTIGLIA | C33: viafossato5 | D33: CANTIANO | E33: ACQUABATTAGLIA | F33: www.acquabattaglia.com | H33: picorri@gmail.com | I33: =IF(BnB[[#This Row],[Test]]="a",BnB[[#This Row],[Indirizzodipostaelettronica]],IF(BnB[[#This Row],[Test]]="b","Non disponibile",IF(BnB[[#This Row],[Test]]="c",BnB[[#This Row],[Indirizzodipostaelettronica]],IF(BnB[[#This Row],[Test]]="d",BnB[[#This Row],[Indirizzodipostaelettronica]],BnB[[#This Row],[Indirizzointernet]])))) -> www.acquabattaglia.com | J33: =IF(BnB[[#This Row],[Test]]="a",BnB[[#This Row],[Indirizzointernet]],IF(BnB[[#This Row],[Test]]="b",CONCATENATE(BnB[[#This Row],[Indirizzointernet]],"; ",BnB[[#This Row],[Indirizzodipostaelettronica]]),IF(BnB[[#This Row],[Test]]="c",BnB[[#This Row],[Indirizzointernet]],IF(BnB[[#This Row],[Test]]="d",BnB[[#This Row],[Indirizzointernet]],BnB[[#This Row],[Indirizzodipostaelettronica]])))) -> picorri@gmail.com
A34: ALLOGGIINAFFITTO | B34: ACQUAMARINA | C34: viaC.Maffei68 | D34: SANBENEDETTODELTRONTO | E34: Non disponibile | F34: www.residenceacquamarina.com | H34: info@appartamentiacquamarina.it | I34: =IF(BnB[[#This Row],[Test]]="a",BnB[[#This Row],[Indirizzodipostaelettronica]],IF(BnB[[#This Row],[Test]]="b","Non disponibile",IF(BnB[[#This Row],[Test]]="c",BnB[[#This Row],[Indirizzodipostaelettronica]],IF(BnB[[#This Row],[Test]]="d",BnB[[#This Row],[Indirizzodipostaelettronica]],BnB[[#This Row],[Indirizzointernet]])))) -> www.residenceacquamarina.com | J34: =IF(BnB[[#This Row],[Test]]="a",BnB[[#This Row],[Indirizzointernet]],IF(BnB[[#This Row],[Test]]="b",CONCATENATE(BnB[[#This Row],[Indirizzointernet]],"; ",BnB[[#This Row],[Indirizzodipostaelettronica]]),IF(BnB[[#This Row],[Test]]="c",BnB[[#This Row],[Indirizzointernet]],IF(BnB[[#This Row],[Test]]="d",BnB[[#This Row],[Indirizzointernet]],BnB[[#This Row],[Indirizzodipostaelettronica]])))) -> info@appartamentiacquamarina.it
... A40: TURISMORURALE | B40: ACQUAVIVAdiCECCHIPEPPINO | C40: contradaacquavivasanpaterniano34 | D40: LOROPICENO | E40: LOROPICENO | F40: www.countryhouseacquaviva.it | H40: p.cecchi@tiscali.it | I40: =IF(BnB[[#This Row],[Test]]="a",BnB[[#This Row],[Indirizzodipostaelettronica]],IF(BnB[[#This Row],[Test]]="b","Non disponibile",IF(BnB[[#This Row],[Test]]="c",BnB[[#This Row],[Indirizzodipostaelettronica]],IF(BnB[[#This Row],[Test]]="d",BnB[[#This Row],[Indirizzodipostaelettronica]],BnB[[#This Row],[Indirizzointernet]])))) -> www.countryhouseacquaviva.it | J40: =IF(BnB[[#This Row],[Test]]="a",BnB[[#This Row],[Indirizzointernet]],IF(BnB[[#This Row],[Test]]="b",CONCATENATE(BnB[[#This Row],[Indirizzointernet]],"; ",BnB[[#This Row],[Indirizzodipostaelettronica]]),IF(BnB[[#This Row],[Test]]="c",BnB[[#This Row],[Indirizzointernet]],IF(BnB[[#This Row],[Test]]="d",BnB[[#This Row],[Indirizzointernet]],BnB[[#This Row],[Indirizzodipostaelettronica]])))) -> p.cecchi@tiscali.it
A41: STABILIMENTIBALNEARI | B41: ACROPOLI | D41: PORTORECANATI | E41: PORTORECANATI | F41: mmonina@tiscali.it | G41: c | H41: www.acropoli-mb.it | I41: =IF(BnB[[#This Row],[Test]]="a",BnB[[#This Row],[Indirizzodipostaelettronica]],IF(BnB[[#This Row],[Test]]="b","Non disponibile",IF(BnB[[#This Row],[Test]]="c",BnB[[#This Row],[Indirizzodipostaelettronica]],IF(BnB[[#This Row],[Test]]="d",BnB[[#This Row],[Indirizzodipostaelettronica]],BnB[[#This Row],[Indirizzointernet]])))) -> www.acropoli-mb.it | J41: =IF(BnB[[#This Row],[Test]]="a",BnB[[#This Row],[Indirizzointernet]],IF(BnB[[#This Row],[Test]]="b",CONCATENATE(BnB[[#This Row],[Indirizzointernet]],"; ",BnB[[#This Row],[Indirizzodipostaelettronica]]),IF(BnB[[#This Row],[Test]]="c",BnB[[#This Row],[Indirizzointernet]],IF(BnB[[#This Row],[Test]]="d",BnB[[#This Row],[Indirizzointernet]],BnB[[#This Row],[Indirizzodipostaelettronica]])))) -> mmonina@tiscali.it
A42: ALBERGHI | B42: ACRUX | C42: viaVittorioVeneto146 | D42: GABICCEMARE | E42: GABICCEMARE | F42: www.hotelacrux.com | H42: info@hotelacrux.com | I42: =IF(BnB[[#This Row],[Test]]="a",BnB[[#This Row],[Indirizzodipostaelettronica]],IF(BnB[[#This Row],[Test]]="b","Non disponibile",IF(BnB[[#This Row],[Test]]="c",BnB[[#This Row],[Indirizzodipostaelettronica]],IF(BnB[[#This Row],[Test]]="d",BnB[[#This Row],[Indirizzodipostaelettronica]],BnB[[#This Row],[Indirizzointernet]])))) -> www.hotelacrux.com | J42: =IF(BnB[[#This Row],[Test]]="a",BnB[[#This Row],[Indirizzointernet]],IF(BnB[[#This Row],[Test]]="b",CONCATENATE(BnB[[#This Row],[Indirizzointernet]],"; ",BnB[[#This Row],[Indirizzodipostaelettronica]]),IF(BnB[[#This Row],[Test]]="c",BnB[[#This Row],[Indirizzointernet]],IF(BnB[[#This Row],[Test]]="d",BnB[[#This Row],[Indirizzointernet]],BnB[[#This Row],[Indirizzodipostaelettronica]])))) -> info@hotelacrux.com
A43: RESIDENZETURISTICOALBERGHIERE | B43: ADA | C43: lungomarealcidedegasperi76 | D43: GROTTAMMARE | E43: GROTTAMMARE | F43: www.residenceada.com | H43: info@residenceada.com | I43: =IF(BnB[[#This Row],[Test]]="a",BnB[[#This Row],[Indirizzodipostaelettronica]],IF(BnB[[#This Row],[Test]]="b","Non disponibile",IF(BnB[[#This Row],[Test]]="c",BnB[[#This Row],[Indirizzodipostaelettronica]],IF(BnB[[#This Row],[Test]]="d",BnB[[#This Row],[Indirizzodipostaelettronica]],BnB[[#This Row],[Indirizzointernet]])))) -> www.residenceada.com | J43: =IF(BnB[[#This Row],[Test]]="a",BnB[[#This Row],[Indirizzointernet]],IF(BnB[[#This Row],[Test]]="b",CONCATENATE(BnB[[#This Row],[Indirizzointernet]],"; ",BnB[[#This Row],[Indirizzodipostaelettronica]]),IF(BnB[[#This Row],[Test]]="c",BnB[[#This Row],[Indirizzointernet]],IF(BnB[[#This Row],[Test]]="d",BnB[[#This Row],[Indirizzointernet]],BnB[[#This Row],[Indirizzodipostaelettronica]])))) -> info@residenceada.com
A44: ALLOGGIINAFFITTO | B44: ADAMOEDEVARESORT | C44: viaCostaVerdesnc | D44: NUMANA | E44: Marcelli | F44: www.adamoedevanumana.it | H44: info@adamoedevanumana.it | I44: =IF(BnB[[#This Row],[Test]]="a",BnB[[#This Row],[Indirizzodipostaelettronica]],IF(BnB[[#This Row],[Test]]="b","Non disponibile",IF(BnB[[#This Row],[Test]]="c",BnB[[#This Row],[Indirizzodipostaelettronica]],IF(BnB[[#This Row],[Test]]="d",BnB[[#This Row],[Indirizzodipostaelettronica]],BnB[[#This Row],[Indirizzointernet]])))) -> www.adamoedevanumana.it | J44: =IF(BnB[[#This Row],[Test]]="a",BnB[[#This Row],[Indirizzointernet]],IF(BnB[[#This Row],[Test]]="b",CONCATENATE(BnB[[#This Row],[Indirizzointernet]],"; ",BnB[[#This Row],[Indirizzodipostaelettronica]]),IF(BnB[[#This Row],[Test]]="c",BnB[[#This Row],[Indirizzointernet]],IF(BnB[[#This Row],[Test]]="d",BnB[[#This Row],[Indirizzointernet]],BnB[[#This Row],[Indirizzodipostaelettronica]])))) -> info@adamoedevanumana.it
A45: ALBERGHI | B45: ADLER | C45: vialemare13 | D45: GABICCEMARE | E45: GABICCEMARE | F45: www.adlerhotel.eu | H45: info@adlerhotel.eu | I45: =IF(BnB[[#This Row],[Test]]="a",BnB[[#This Row],[Indirizzodipostaelettronica]],IF(BnB[[#This Row],[Test]]="b","Non disponibile",IF(BnB[[#This Row],[Test]]="c",BnB[[#This Row],[Indirizzodipostaelettronica]],IF(BnB[[#This Row],[Test]]="d",BnB[[#This Row],[Indirizzodipostaelettronica]],BnB[[#This Row],[Indirizzointernet]])))) -> www.adlerhotel.eu | J45: =IF(BnB[[#This Row],[Test]]="a",BnB[[#This Row],[Indirizzointernet]],IF(BnB[[#This Row],[Test]]="b",CONCATENATE(BnB[[#This Row],[Indirizzointernet]],"; ",BnB[[#This Row],[Indirizzodipostaelettronica]]),IF(BnB[[#This Row],[Test]]="c",BnB[[#This Row],[Indirizzointernet]],IF(BnB[[#This Row],[Test]]="d",BnB[[#This Row],[Indirizzointernet]],BnB[[#This Row],[Indirizzodipostaelettronica]])))) -> info@adlerhotel.eu
...

Sheet Menu
B2: [Selezionare la struttura dal menu a tendina] | D2: LOCALITÀ J | E2: =+_xlfn.XLOOKUP(RICERCA!$C$4,BnB[Denominazione],BnB[Localita],"Non disponibile",0,1) -> SIROLO
B3: ='Strutture ricettive'!B2 -> 124AFFITTACAMERE
B4: ='Strutture ricettive'!B3 -> 2000diDIAMANTINIASSUNTA
B5: ='Strutture ricettive'!B4 -> 30NODI
B6: ='Strutture ricettive'!B5 -> 3JOLIE
B7: ='Strutture ricettive'!B6 -> 45.COM
B8: ='Strutture ricettive'!B7 -> 4PINI
B9: ='Strutture ricettive'!B8 -> 4SORELLE
B10: ='Strutture ricettive'!B9 -> 4STAGIONI
B11: ='Strutture ricettive'!B10 -> 5ALBERI
B12: ='Strutture ricettive'!B11 -> 5COLLI
B13: ='Strutture ricettive'!B12 -> 9CAMERE
B14: ='Strutture ricettive'!B13 -> A3PASSI
... B6260: ='Strutture ricettive'!B6259 -> ZONA31

Sheet RICERCA
B2: RICERCA STRUTTURA
B4: NOME STRUTTURA | C4: 3JOLIE
B5: CITTA' | C5: =+_xlfn.XLOOKUP($C$4,BnB[Denominazione],BnB[Città],"Non disponibile",0,1) -> SIROLO
B6: INDIRIZZO | C6: =+_xlfn.XLOOKUP($C$4,BnB[Denominazione],BnB[Indirizzo],"Non disponibile",0,1) -> vialeCadutidelLavoro1
B7: EMAIL | C7: =+_xlfn.XLOOKUP($C$4,BnB[Denominazione],BnB[IndirizzodipostaelettronicaClean],"Non disponibile",0,1) -> info@cameresirolo.com
B8: INDIRIZZO WEB | C8: =+_xlfn.XLOOKUP($C$4,BnB[Denominazione],BnB[IndirizzointernetClean],"Non disponibile",0,1) -> www.cameresirolo.com
B9: Numero totale strutture | C9: =COUNTA(BnB[Categoria]) -> 6258
B10: Numero strutture per LOCALITA' | C10: =IF(Menu!$E$2="Non disponibile","Dato non disponibile",COUNTIF(BnB[Localita],Menu!$E$2)) -> 49
